<?xml version="1.0"?>
<robot name="hamal" xmlns:xacro="http://ros.org/wiki/xacro">
  <xacro:include filename="$(find hamal_description)/urdf/common_properties.xacro" />
  <xacro:include filename="$(find hamal_description)/urdf/moobot.gazebo.xacro" />

  <!-- AGV Base -->

  <link name="base_link">
    <visual>
      <origin xyz="0 0 0" rpy="0 0 0" />
      <geometry>
        <mesh filename="package://hamal_description/mesh/logos_maxi_base.stl" scale="0.001 0.001 0.001" />
      </geometry>
    </visual>
    <!-- -->
    <collision>
      <origin xyz="0 0 0" rpy="0 0 0" />
      <geometry>
        <mesh filename="package://hamal_description/mesh/logos_maxi_base.stl" scale="0.001 0.001 0.001" />
        <!-- <box size="1.655 0.784 0.23" /> -->
      </geometry>
    </collision>

    <inertial>
      <origin xyz="0 0 0" rpy="0 0 0" />
      <mass value="289" />
      <inertia ixx="28.034" ixy="0.669" ixz="-2.355"
        iyy="96.827" iyz="0.232"
        izz="108.149" />
    </inertial>
  </link>

  <link name="base_footprint" />

  <joint name="base_joint" type="fixed">
    <parent link="base_footprint" />
    <child link="base_link" />
    <origin xyz="0 0 0" rpy="0 0 0" />
  </joint>


  <!-- ******************** FRONT ********************-->

  <!-- Front Buggy Joint -->
  <joint name="front_buggy_joint" type="continuous">
    <parent link="base_link" />
    <child link="front_buggy_link" />
    <origin xyz="0.4125 0 0.1435" rpy="0 -1.570796 3.141592" />
    <axis xyz="0 0 1" />
    <limit effort="2" lower="-0.08726" upper="0.08726" velocity="1.0" />
  </joint>

  <!-- Front Buggy Link -->
  <link name="front_buggy_link">
    <visual>
      <origin xyz="0 0 0" rpy="0 0 0" />
      <geometry>
        <mesh filename="package://hamal_description/mesh/front_buggy_link.stl" scale="0.001 0.001 0.001" />
      </geometry>
    </visual>

    <inertial>
      <origin xyz="0 0 0" rpy="0 0 0" />
      <mass value="9.515" />
      <inertia ixx="0.302" ixy="-0.00000001" ixz="0"
        iyy="0.0279" iyz="0"
        izz="0.316" />
    </inertial>
  </link>

  <!-- Front - Right -->
  <!-- Top Part Joint-->
  <joint name="top_part_right_joint" type="fixed">
    <parent link="front_buggy_link" />
    <child link="top_part_right_link" />
    <origin xyz="0.0415 0.2245 -0.0025" rpy="0 -1.570796 0" />
  </joint>

  <!-- Top Part Link-->
  <link name="top_part_right_link">
    <visual>
      <origin xyz="0 0 0" rpy="0 0 0" />
      <geometry>
        <mesh filename="package://hamal_description/mesh/top_part.stl" scale="0.001 0.001 0.001" />
      </geometry>
    </visual>

    <inertial>
      <mass value="1.5" />
      <origin xyz="0 0 0" />
      <inertia ixx="0.004" ixy="0.0" ixz="0.0"
        iyy="0.003" iyz="0.0"
        izz="0.007" />
    </inertial>
  </link>


  <!-- Bottom Part Joint-->
  <joint name="bottom_part_right_joint" type="continuous">
    <parent link="top_part_right_link" />
    <child link="bottom_part_right_link" />
    <origin xyz="0 0 0" rpy="0 0 0" />
    <axis xyz="0 0 1" />
  </joint>

  <!-- Bottom Part Link-->
  <link name="bottom_part_right_link">
    <visual>
      <origin xyz="0 0 0" rpy="0 0 0" />
      <geometry>
        <mesh filename="package://hamal_description/mesh/bottom_part.stl" scale="0.001 0.001 0.001" />
      </geometry>
    </visual>

    <inertial>
      <mass value="5.5" />
      <origin xyz="0 0 0" />
      <inertia ixx="0.035" ixy="0.0" ixz="0.008"
        iyy="0.03" iyz="0.0"
        izz="0.018" />
    </inertial>
  </link>


  <!-- FR Wheel -1 Joint -->
  <joint name="FR_wheel_1_joint" type="continuous">
    <parent link="bottom_part_right_link" />
    <child link="FR_wheel_1_link" />
    <origin xyz="0.05 -0.031 0.1225" rpy="0 1.570796 1.570796" />
    <axis xyz="0 0 1" />
  </joint>

  <!-- FR Wheel -1 Link -->
  <link name="FR_wheel_1_link">
    <visual>
      <origin xyz="0 0 0" rpy="0 0 0" />
      <geometry>
        <mesh filename="package://hamal_description/mesh/wheel.stl" scale="0.001 0.001 0.001" />
      </geometry>
    </visual>

    <collision>
      <origin xyz="0 0 0" rpy="0 0 0" />
      <geometry>
        <cylinder length="0.059" radius="0.0625" />
      </geometry>
    </collision>

    <inertial>
      <mass value="2.1" />
      <origin xyz="0 0 0" />
      <inertia ixx="0.002" ixy="0.0" ixz="0.0"
        iyy="0.002" iyz="0.0"
        izz="0.004" />
    </inertial>
  </link>

  <!-- FR Wheel -2 Joint -->
  <joint name="FR_wheel_2_joint" type="continuous">
    <parent link="bottom_part_right_link" />
    <child link="FR_wheel_2_link" />
    <origin xyz="0.05 0.031 0.1225" rpy="0 1.570796 1.570796" />
    <axis xyz="0 0 1" />
  </joint>

  <!-- FR Wheel -2 Link -->
  <link name="FR_wheel_2_link">
    <visual>
      <origin xyz="0 0 0" rpy="0 0 0" />
      <geometry>
        <mesh filename="package://hamal_description/mesh/wheel.stl" scale="0.001 0.001 0.001" />
      </geometry>
    </visual>

    <collision>
      <origin xyz="0 0 0" rpy="0 0 0" />
      <geometry>
        <cylinder length="0.059" radius="0.0625" />
      </geometry>
    </collision>

    <inertial>
      <mass value="2.1" />
      <origin xyz="0 0 0" />
      <inertia ixx="0.002" ixy="0.0" ixz="0.0"
        iyy="0.002" iyz="0.0"
        izz="0.004" />
    </inertial>
  </link>


  <!-- FRONT - LEFT -->
  <!-- Top Part Joint-->
  <joint name="top_part_left_joint" type="fixed">
    <parent link="front_buggy_link" />
    <child link="top_part_left_link" />
    <origin xyz="0.0415 -0.2245 -0.0025" rpy="0 -1.570796 0" />
  </joint>

  <!-- Top Part Link-->
  <link name="top_part_left_link">
    <visual>
      <origin xyz="0 0 0" rpy="0 0 0" />
      <geometry>
        <mesh filename="package://hamal_description/mesh/top_part.stl" scale="0.001 0.001 0.001" />
      </geometry>
    </visual>

    <inertial>
      <mass value="1.5" />
      <origin xyz="0 0 0" />
      <inertia ixx="0.004" ixy="0.0" ixz="0.0"
        iyy="0.003" iyz="0.0"
        izz="0.007" />
    </inertial>
  </link>

  <!-- Bottom Part Joint-->
  <joint name="bottom_part_left_joint" type="continuous">
    <parent link="top_part_left_link" />
    <child link="bottom_part_left_link" />
    <origin xyz="0 0 0" rpy="0 0 0" />
    <axis xyz="0 0 1" />

  </joint>

  <!-- Bottom Part Link-->
  <link name="bottom_part_left_link">
    <visual>
      <origin xyz="0 0 0" rpy="0 0 0" />
      <geometry>
        <mesh filename="package://hamal_description/mesh/bottom_part.stl" scale="0.001 0.001 0.001" />
      </geometry>
    </visual>

    <inertial>
      <mass value="5.5" />
      <origin xyz="0 0 0" />
      <inertia ixx="0.035" ixy="0.0" ixz="0.008"
        iyy="0.03" iyz="0.0"
        izz="0.018" />
    </inertial>
  </link>

  <!-- FL Wheel - 1 Joint -->
  <joint name="FL_wheel_1_joint" type="continuous">
    <parent link="bottom_part_left_link" />
    <child link="FL_wheel_1_link" />
    <origin xyz="0.05 -0.031 0.1225" rpy="0 1.570796 1.570796" />
    <axis xyz="0 0 1" />
  </joint>

  <!-- FL Wheel - 1 Link -->
  <link name="FL_wheel_1_link">
    <visual>
      <origin xyz="0 0 0" rpy="0 0 0" />
      <geometry>
        <mesh filename="package://hamal_description/mesh/wheel.stl" scale="0.001 0.001 0.001" />
      </geometry>
    </visual>

    <collision>
      <origin xyz="0 0 0" rpy="0 0 0" />
      <geometry>
        <cylinder length="0.059" radius="0.0625" />
      </geometry>
    </collision>

    <inertial>
      <mass value="2.1" />
      <origin xyz="0 0 0" />
      <inertia ixx="0.002" ixy="0.0" ixz="0.0"
        iyy="0.002" iyz="0.0"
        izz="0.004" />
    </inertial>
  </link>

  <!-- FL Wheel - 2 Joint -->
  <joint name="FL_wheel_2_joint" type="continuous">
    <parent link="bottom_part_left_link" />
    <child link="FL_wheel_2_link" />
    <origin xyz="0.05 0.031 0.1225" rpy="0 1.570796 1.570796" />
    <axis xyz="0 0 1" />
  </joint>

  <!-- FL Wheel - 2 Link -->
  <link name="FL_wheel_2_link">
    <visual>
      <origin xyz="0 0 0" rpy="0 0 0" />
      <geometry>
        <mesh filename="package://hamal_description/mesh/wheel.stl" scale="0.001 0.001 0.001" />
      </geometry>
    </visual>

    <collision>
      <origin xyz="0 0 0" rpy="0 0 0" />
      <geometry>
        <cylinder length="0.059" radius="0.0625" />
      </geometry>
    </collision>

    <inertial>
      <mass value="2.1" />
      <origin xyz="0 0 0" />
      <inertia ixx="0.002" ixy="0.0" ixz="0.0"
        iyy="0.002" iyz="0.0"
        izz="0.004" />
    </inertial>
  </link>

  <!-- ******************** REAR ********************-->

  <!-- Rear Right Buggy Joint  -->
  <joint name="rear_right_buggy_joint" type="continuous">
    <parent link="base_link" />
    <child link="rear_right_buggy_link" />
    <origin xyz="-0.17614 -0.2235 0.105" rpy="1.570796 0 0" />
    <axis xyz="0 0 1" />
  </joint>

  <!-- Rear Right Buggy Link  -->
  <link name="rear_right_buggy_link">
    <visual>
      <origin xyz="0 0 0" rpy="0 0 1.570796" />
      <geometry>
        <mesh filename="package://hamal_description/mesh/rear_right_buggy.stl" scale="0.001 0.001 0.001" />
      </geometry>
    </visual>

    <inertial>
      <mass value="29.173" />
      <origin xyz="0 0 0" />
      <inertia ixx="0.820" ixy="0.021" ixz="0"
        iyy="0.154" iyz="0.045"
        izz="0.768" />
    </inertial>
  </link>

  <!-- Rear Right Mid Wheel Joint  -->
  <joint name="RRM_wheel_joint" type="continuous">
    <parent link="rear_right_buggy_link" />
    <child link="RRM_wheel_link" />
    <origin xyz="0.1769 0 0" rpy="0 3.14 0" />
    <axis xyz="0 0 1" />
    <dynamics damping="1" friction="0" />
    <limit effort="2" velocity="1.0" />
  </joint>

  <!-- Rear Right Mid Wheel Link  -->
  <link name="RRM_wheel_link">
    <visual>
      <origin xyz="0 0 0" rpy="1.570796 0 0" />
      <geometry>
        <mesh filename="package://hamal_description/mesh/mid_wheel.stl" scale="0.001 0.001 0.001" />
      </geometry>
    </visual>

    <collision>
      <origin xyz="0 0 0" rpy="0 0 0" />
      <geometry>
        <cylinder length="0.0835" radius="0.105" />
      </geometry>
    </collision>

    <inertial>
      <mass value="1.5" />
      <origin xyz="0 0 0" />
      <inertia ixx="0.006751005" ixy="0.0" ixz="0.000001355"
        iyy="0.011935781" iyz="0.0"
        izz="0.006746312" />
    </inertial>
  </link>


  <!-- Arka Avareler-->
  <!-- REAR - RIGHT -->

  <!-- Top Part Joint -->
  <joint name="r_top_part_right_joint" type="fixed">
    <parent link="rear_right_buggy_link" />
    <child link="r_top_part_right_link" />
    <origin xyz="-0.218 0.08 -0.00" rpy="1.570796 0 0" />
  </joint>

  <!-- Top Part Link -->
  <link name="r_top_part_right_link">
    <visual>
      <origin xyz="0 0 0" rpy="0 0 0" />
      <geometry>
        <mesh filename="package://hamal_description/mesh/top_part.stl" scale="0.001 0.001 0.001" />
      </geometry>
    </visual>

    <inertial>
      <mass value="1.5" />
      <origin xyz="0 0 0" />
      <inertia ixx="0.004" ixy="0.0" ixz="0.0"
        iyy="0.003" iyz="0.0"
        izz="0.007" />
    </inertial>
  </link>

  <!-- Bottom Part Joint -->
  <joint name="r_bottom_part_right_joint" type="continuous">
    <parent link="r_top_part_right_link" />
    <child link="r_bottom_part_right_link" />
    <origin xyz="0 0 0" rpy="0 0 0" />
    <axis xyz="0 0 1" />
  </joint>

  <!-- Bottom Part Link  -->
  <link name="r_bottom_part_right_link">
    <visual>
      <origin xyz="0 0 0" rpy="0 0 0" />
      <geometry>
        <mesh filename="package://hamal_description/mesh/bottom_part.stl" scale="0.001 0.001 0.001" />
      </geometry>
    </visual>

    <inertial>
      <mass value="5.5" />
      <origin xyz="0 0 0" />
      <inertia ixx="0.035" ixy="0.0" ixz="0.008"
        iyy="0.03" iyz="0.0"
        izz="0.018" />
    </inertial>
  </link>

  <!-- RR Wheel -1 Joint -->
  <joint name="RR_wheel_1_joint" type="continuous">
    <parent link="r_bottom_part_right_link" />
    <child link="RR_wheel_1_link" />
    <origin xyz="0.05 -0.031 0.1225" rpy="0 1.570796 1.570796" />
    <axis xyz="0 0 1" />
  </joint>

  <!-- RR Wheel -1 Link -->
  <link name="RR_wheel_1_link">
    <visual>
      <origin xyz="0 0 0" rpy="0 0 0" />
      <geometry>
        <mesh filename="package://hamal_description/mesh/wheel.stl" scale="0.001 0.001 0.001" />
      </geometry>
    </visual>

    <collision>
      <origin xyz="0 0 0" rpy="0 0 0" />
      <geometry>
        <cylinder length="0.059" radius="0.0625" />
      </geometry>
    </collision>

    <inertial>
      <mass value="2.1" />
      <origin xyz="0 0 0" />
      <inertia ixx="0.002" ixy="0.0" ixz="0.0"
        iyy="0.002" iyz="0.0"
        izz="0.004" />
    </inertial>
  </link>

  <!-- RR Wheel -2 Joint -->
  <joint name="RR_wheel_2_joint" type="continuous">
    <parent link="r_bottom_part_right_link" />
    <child link="RR_wheel_2_link" />
    <origin xyz="0.05 0.031 0.1225" rpy="0 1.570796 1.570796" />
    <axis xyz="0 0 1" />
  </joint>

  <!-- RR Wheel -2 Link -->
  <link name="RR_wheel_2_link">
    <visual>
      <origin xyz="0 0 0" rpy="0 0 0" />
      <geometry>
        <mesh filename="package://hamal_description/mesh/wheel.stl" scale="0.001 0.001 0.001" />
      </geometry>
    </visual>

    <collision>
      <origin xyz="0 0 0" rpy="0 0 0" />
      <geometry>
        <cylinder length="0.059" radius="0.0625" />
      </geometry>
    </collision>

    <inertial>
      <mass value="2.1" />
      <origin xyz="0 0 0" />
      <inertia ixx="0.002" ixy="0.0" ixz="0.0"
        iyy="0.002" iyz="0.0"
        izz="0.004" />
    </inertial>
  </link>


  <!-- REAR - LEFT -->

  <!-- Rear Left Buggy Joint  -->
  <joint name="rear_left_buggy_joint" type="continuous">
    <parent link="base_link" />
    <child link="rear_left_buggy_link" />
    <origin xyz="-0.17614 0.2235 0.105" rpy="1.570796 0 0" />
    <axis xyz="0 0 1" />
  </joint>

  <!-- Rear Left Buggy Link  -->
  <link name="rear_left_buggy_link">
    <visual>
      <origin xyz="0 0 0" rpy="0 0 1.570796" />
      <geometry>
        <mesh filename="package://hamal_description/mesh/rear_left_buggy.stl" scale="0.001 0.001 0.001" />
      </geometry>
    </visual>

    <inertial>
      <mass value="29.173" />
      <origin xyz="0 0 0" />
      <inertia ixx="0.820" ixy="0.021" ixz="0"
        iyy="0.154" iyz="0.045"
        izz="0.768" />
    </inertial>
  </link>

  <!-- Rear Left Mid Wheel Joint  -->
  <joint name="RLM_wheel_joint" type="continuous">
    <parent link="rear_left_buggy_link" />
    <child link="RLM_wheel_link" />
    <origin xyz="0.1769 0 0" rpy="0 3.14 0" />
    <axis xyz="0 0 1" />
    <dynamics damping="1" friction="0" />
    <limit effort="2" velocity="1.0" />
  </joint>

  <!-- Rear Left Mid Wheel Link  -->
  <link name="RLM_wheel_link">
    <visual>
      <origin xyz="0 0 0" rpy="1.570796 0 0" />
      <geometry>
        <mesh filename="package://hamal_description/mesh/mid_wheel.stl" scale="0.001 0.001 0.001" />
      </geometry>
    </visual>

    <collision>
      <origin xyz="0 0 0" rpy="0 0 0" />
      <geometry>
        <cylinder length="0.0835" radius="0.105" />
      </geometry>
    </collision>

    <inertial>
      <mass value="1.5" />
      <origin xyz="0 0 0" />
      <inertia ixx="0.006751005" ixy="0.0" ixz="0.000001355"
        iyy="0.011935781" iyz="0.0"
        izz="0.006746312" />
    </inertial>
  </link>


  <!-- Arka Avareler-->
  <!-- REAR - LEFT -->

  <!-- Top Part Joint -->
  <joint name="r_top_buggy_left_joint" type="fixed">
    <parent link="rear_left_buggy_link" />
    <child link="r_top_buggy_left_link" />
    <origin xyz="-0.218 0.08 -0.00" rpy="1.570796 0 0" />
  </joint>

  <!-- Top Part Link -->
  <link name="r_top_buggy_left_link">
    <visual>
      <origin xyz="0 0 0" rpy="0 0 0" />
      <geometry>
        <mesh filename="package://hamal_description/mesh/top_part.stl" scale="0.001 0.001 0.001" />
      </geometry>
    </visual>

    <inertial>
      <mass value="1.5" />
      <origin xyz="0 0 0" />
      <inertia ixx="0.004" ixy="0.0" ixz="0.0"
        iyy="0.003" iyz="0.0"
        izz="0.007" />
    </inertial>
  </link>

  <!-- Bottom Part Joint -->
  <joint name="r_bottom_buggy_left_joint" type="continuous">
    <parent link="r_top_buggy_left_link" />
    <child link="r_bottom_buggy_left_link" />
    <origin xyz="0 0 0" rpy="0 0 0" />
    <axis xyz="0 0 1" />
  </joint>

  <!-- Bottom Part Link -->
  <link name="r_bottom_buggy_left_link">
    <visual>
      <origin xyz="0 0 0" rpy="0 0 0" />
      <geometry>
        <mesh filename="package://hamal_description/mesh/bottom_part.stl" scale="0.001 0.001 0.001" />
      </geometry>
    </visual>

    <inertial>
      <mass value="5.5" />
      <origin xyz="0 0 0" />
      <inertia ixx="0.035" ixy="0.0" ixz="0.008"
        iyy="0.03" iyz="0.0"
        izz="0.018" />
    </inertial>
  </link>


  <!-- RL Wheel - 1 Joint -->
  <joint name="RL_wheel_1_joint" type="continuous">
    <parent link="r_bottom_buggy_left_link" />
    <child link="RL_wheel_1_link" />
    <origin xyz="0.05 -0.031 0.1225" rpy="0 1.570796 1.570796" />
    <axis xyz="0 0 1" />
  </joint>

  <!-- RL Wheel - 1 Link -->
  <link name="RL_wheel_1_link">
    <visual>
      <origin xyz="0 0 0" rpy="0 0 0" />
      <geometry>
        <mesh filename="package://hamal_description/mesh/wheel.stl" scale="0.001 0.001 0.001" />
      </geometry>
    </visual>

    <collision>
      <origin xyz="0 0 0" rpy="0 0 0" />
      <geometry>
        <cylinder length="0.059" radius="0.0625" />
      </geometry>
    </collision>

    <inertial>
      <mass value="2.1" />
      <origin xyz="0 0 0" />
      <inertia ixx="0.002" ixy="0.0" ixz="0.0"
        iyy="0.002" iyz="0.0"
        izz="0.004" />
    </inertial>
  </link>

  <!-- RL Wheel - 2 Joint -->
  <joint name="RL_wheel_2_joint" type="continuous">
    <parent link="r_bottom_buggy_left_link" />
    <child link="RL_wheel_2_link" />
    <origin xyz="0.05 0.031 0.1225" rpy="0 1.570796 1.570796" />
    <axis xyz="0 0 1" />
  </joint>

  <!-- RL Wheel - 2 Link -->
  <link name="RL_wheel_2_link">
    <visual>
      <origin xyz="0 0 0" rpy="0 0 0" />
      <geometry>
        <mesh filename="package://hamal_description/mesh/wheel.stl" scale="0.001 0.001 0.001" />
      </geometry>
    </visual>

    <collision>
      <origin xyz="0 0 0" rpy="0 0 0" />
      <geometry>
        <cylinder length="0.059" radius="0.0625" />
      </geometry>
    </collision>

    <inertial>
      <mass value="2.1" />
      <origin xyz="0 0 0" />
      <inertia ixx="0.002" ixy="0.0" ixz="0.0"
        iyy="0.002" iyz="0.0"
        izz="0.004" />
    </inertial>
  </link>


  <!-- Scanner -->
  <!-- Front Scanner -->
  <joint name="front_scan_joint" type="fixed">
    <parent link="base_link" />
    <child link="front_scan_link" />
    <origin xyz="0.80612 0.3712 0.185" rpy="3.141592 0 0.7853981634" />
  </joint>

  <link name="front_scan_link">
    <visual>
      <origin xyz="0 0 0" rpy="0 0 0" />
      <geometry>
        <mesh filename="package://hamal_description/mesh/nanoscan.stl" scale="0.001 0.001 0.001" />
      </geometry>
    </visual>
    
    <inertial>
      <mass value="0.114" />
      <origin xyz="0 0 0" />
      <inertia ixx="0.001" ixy="0.0" ixz="0.0"
        iyy="0.001" iyz="0.0"
        izz="0.001" />
    </inertial>
  </link>

  <joint name="rear_scan_joint" type="fixed">
    <parent link="base_link" />
    <child link="rear_scan_link" />
    <origin xyz="-0.80612 -0.3712 0.185" rpy="3.141592 0  3.926990817 " />
  </joint>

  <link name="rear_scan_link">
    <visual>
      <origin xyz="0 0 0" rpy="0 0 0" />
      <geometry>
        <mesh filename="package://hamal_description/mesh/nanoscan.stl" scale="0.001 0.001 0.001" />
      </geometry>
    </visual>

    <inertial>
      <mass value="0.114" />
      <origin xyz="0 0 0" />
      <inertia ixx="0.001" ixy="0.0" ixz="0.0"
        iyy="0.001" iyz="0.0"
        izz="0.001" />
    </inertial>
  </link>

</robot>
